task.set_exception(Exception('xxx'))